<?xml version='1.0'?>
<sdf version='1.6'>
  <model name='gimbal_small_2d_edit'>
    <pose>0 0 0.18 0 0 0</pose>

    <link name='base_link'>
       <inertial>
        <mass>0.2</mass>
        <inertia>
          <ixx>0.0001</ixx>
          <ixy>0</ixy>
          <ixz>0</ixz>
          <iyy>0.0001</iyy>
          <iyz>0</iyz>
          <izz>0.0001</izz>
        </inertia>
      </inertial>

      <visual name='base_main_viz'>
        <geometry>
         <mesh>
           <scale>0.001 0.001 0.001</scale>
           <uri>model://gimbal_small_2d_edit/meshes/base_main.dae</uri>
         </mesh>
        </geometry>
        <material>
          <script>
            <uri>file://media/materials/scripts/gazebo.material</uri>
            <name>Gazebo/FlatBlack</name>
          </script>
        </material>
      </visual>

     <visual name='base_arm_viz'>
        <geometry>
         <mesh>
           <scale>0.001 0.001 0.001</scale>
           <uri>model://gimbal_small_2d_edit/meshes/base_arm.dae</uri>
         </mesh>
        </geometry>
        <material>
          <script>
            <uri>file://media/materials/scripts/gazebo.material</uri>
            <name>Gazebo/FlatBlack</name>
          </script>
        </material>
      </visual>

      <collision name='base_col'>
        <pose>0.01 0.075 -0.025 0 0 0</pose>
        <geometry>
          <box>
            <size>0.1 0.05 0.15</size>
          </box>
        </geometry>
        <surface>
          <friction>
            <ode>
              <mu>1</mu>
              <mu2>1</mu2>
              <fdir1>0 0 0</fdir1>
              <slip1>0</slip1>
              <slip2>0</slip2>
            </ode>
          </friction>
        </surface>
      </collision>
    </link>

    <link name='tilt_link'>
       <inertial>
        <mass>0.01</mass>
        <inertia>
          <ixx>0.00001</ixx>
          <ixy>0</ixy>
          <ixz>0</ixz>
          <iyy>0.00001</iyy>
          <iyz>0</iyz>
          <izz>0.00001</izz>
        </inertia>
      </inertial>
     <visual name='tilt_viz'>
        <pose>0 0 -0.005 0 0 0</pose>
        <geometry>
         <mesh>
           <scale>0.001 0.001 0.001</scale>
           <uri>model://gimbal_small_2d_edit/meshes/tilt.dae</uri>
         </mesh>
        </geometry>
        <material>
          <script>
            <uri>file://media/materials/scripts/gazebo.material</uri>
            <name>Gazebo/Grey</name>
          </script>
        </material>
      </visual>

     <collision name='tilt_col'>
        <pose>0 0 -0.005 0 0 0</pose>
        <geometry>
         <mesh>
           <scale>0.001 0.001 0.001</scale>
           <uri>model://gimbal_small_2d_edit/meshes/tilt.dae</uri>
         </mesh>
        </geometry>
      </collision>

      <visual name='camera_viz'>
        <pose>0 0 0.02 0 0 0</pose>
        <geometry>
          <cylinder>
            <radius>0.025</radius>
            <length>0.050</length>
          </cylinder>
        </geometry>

         <material>
          <script>
            <uri>file://media/materials/scripts/gazebo.material</uri>
            <name>Gazebo/Grey</name>
          </script>
        </material>
     </visual>

      <collision name='camera_col'>
        <pose>0 0 0.02 0 0 0</pose>
        <geometry>
          <cylinder>
            <radius>0.025</radius>
            <length>0.050</length>
          </cylinder>
        </geometry>
     </collision>

      <sensor name="camera" type="camera">
        <pose>0 0 0 -1.57 -1.57 0</pose>
        <camera>
          <horizontal_fov>1.085</horizontal_fov>
          <image>
            <width>640</width>
            <height>480</height>
          </image>
          <clip>
            <near>0.05</near>
            <far>15000</far>
          </clip>
        </camera>

        <plugin name="camera_plugin" filename="libgazebo_ros_camera.so">
          <cameraName>camera_ros</cameraName>
          <imageTopicName>/camera/color/image_raw</imageTopicName>
          <cameraInfoTopicName>/camera/color/camera_info</cameraInfoTopicName>
          <frameName>camera_link</frameName>
          <always_on>1</always_on>
          <update_rate>30</update_rate>
          <visualize>1</visualize>
        </plugin>

      </sensor>

    </link>

    <link name='laser_link'>
       <pose>0.0 0.0 0.05 0 0 0</pose>
       <inertial>
        <mass>0.002</mass>
        <inertia>
          <ixx>0.000001</ixx>
          <ixy>0</ixy>
          <ixz>0</ixz>
          <iyy>0.0001</iyy>
          <iyz>0</iyz>
          <izz>0.000001</izz>
        </inertia>
      </inertial>

      <visual name='base_main_viz'>
        <geometry>
          <box>
            <size>0.01 0.01 0.01</size>
          </box>
        </geometry>
        <material>
          <script>
            <uri>file://media/materials/scripts/gazebo.material</uri>
            <name>Gazebo/Orange</name>
          </script>
        </material>
      </visual>

      <collision name='base_col'>
        
        <geometry>
          <box>
            <size>0.01 0.01 0.01</size>
          </box>
        </geometry>
        <surface>
          <friction>
            <ode>
              <mu>1</mu>
              <mu2>1</mu2>
              <fdir1>0 0 0</fdir1>
              <slip1>0</slip1>
              <slip2>0</slip2>
            </ode>
          </friction>
        </surface>
      </collision>

      <sensor type="ray" name="head_hokuyo_sensor">
        <pose>0 0 0 0 0 -1.5708</pose>
        <visualize>1</visualize>
        <update_rate>40</update_rate>
        <ray>
          <scan>
            <horizontal>
              <samples>5</samples>
              <resolution>1</resolution>
              <min_angle>-0.05</min_angle>
              <max_angle>0.05</max_angle>
            </horizontal>
          </scan>
          <range>
            <min>0.075</min>
            <max>30.0</max>
            <resolution>0.01</resolution>
          </range>
          <noise>
            <type>gaussian</type>
            <mean>0.0</mean>
            <stddev>0.01</stddev>
          </noise>
        </ray>
        <plugin name="gazebo_ros_head_hokuyo_controller" filename="libgazebo_ros_laser.so">
          <topicName>/arducopter/laser/scan</topicName>
          <frameName>base_link</frameName>
        </plugin>
      </sensor>
    </link>

    <joint name="laser_joint" type="fixed">
      <parent>base_link</parent>
      <child>laser_link</child>
    </joint>

    <joint name='tilt_joint' type='revolute'>
       <parent>base_link</parent>
       <child>tilt_link</child>

      <physics>
        <ode>
          <implicit_spring_damper>1</implicit_spring_damper>
        </ode>
      </physics>

      <axis>
        <xyz>1 0 0</xyz>
        <dynamics>
          <damping>0.5</damping>
        </dynamics>
        <use_parent_model_frame>1</use_parent_model_frame>
        <limit>
          <lower>-0.1</lower>
          <upper>3.14159265</upper>
          <effort>10</effort>
          <velocity>-1</velocity>
        </limit>
      </axis>
      <pose>0 0 0.02 0 0 0</pose>
    </joint>

    <plugin name="gimbal_small_2d_edit" filename="libGimbalSmall2dPlugin.so">
      <joint>tilt_joint</joint>
    </plugin>
  </model>
</sdf>
